<sdf version='1.6'>
  <world name='default'>
    <plugin name="hello" filename="libhello.so"/>
    <model name='ground_plane'>
      <static>1</static>
      <link name='link'>
        <collision name='collision'>
          <geometry>
            <plane>
              <normal>0 0 1</normal>
              <size>100 100</size>
            </plane>
          </geometry>
          <surface>
            <friction>
              <ode>
                <mu>100</mu>
                <mu2>50</mu2>
              </ode>
              <torsional>
                <ode/>
              </torsional>
            </friction>
            <contact>
              <ode/>
            </contact>
            <bounce/>
          </surface>
          <max_contacts>10</max_contacts>
        </collision>
        <visual name='visual'>
          <cast_shadows>0</cast_shadows>
          <geometry>
            <plane>
              <normal>0 0 1</normal>
              <size>100 100</size>
            </plane>
          </geometry>
          <material>
            <script>
              <uri>file://media/materials/scripts/gazebo.material</uri>
              <name>Gazebo/Grey</name>
            </script>
          </material>
        </visual>
        <self_collide>0</self_collide>
        <kinematic>0</kinematic>
      </link>
    </model>
    <gravity>0 0 -9.8</gravity>
    <magnetic_field>6e-06 2.3e-05 -4.2e-05</magnetic_field>
    <atmosphere type='adiabatic'/>
    <physics name='default_physics' default='0' type='ode'>
      <max_step_size>0.001</max_step_size>
      <real_time_factor>1</real_time_factor>
      <real_time_update_rate>1000</real_time_update_rate>
    </physics>
    <scene>
      <ambient>0.4 0.4 0.4 1</ambient>
      <background>0.7 0.7 0.7 1</background>
      <shadows>1</shadows>
    </scene>
    <spherical_coordinates>
      <surface_model>EARTH_WGS84</surface_model>
      <latitude_deg>0</latitude_deg>
      <longitude_deg>0</longitude_deg>
      <elevation>0</elevation>
      <heading_deg>0</heading_deg>
    </spherical_coordinates>
    <model name='mybuilding'>
      <pose frame=''>-13.9308 -0.426632 0 0 -0 0</pose>
      <link name='Wall_0'>
        <collision name='Wall_0_Collision'>
          <geometry>
            <box>
              <size>12 0.15 2.5</size>
            </box>
          </geometry>
          <pose frame=''>0 0 1.25 0 -0 0</pose>
          <max_contacts>10</max_contacts>
          <surface>
            <contact>
              <ode/>
            </contact>
            <bounce/>
            <friction>
              <torsional>
                <ode/>
              </torsional>
              <ode/>
            </friction>
          </surface>
        </collision>
        <visual name='Wall_0_Visual'>
          <pose frame=''>0 0 1.25 0 -0 0</pose>
          <geometry>
            <box>
              <size>12 0.15 2.5</size>
            </box>
          </geometry>
          <material>
            <script>
              <uri>file://media/materials/scripts/gazebo.material</uri>
              <name>Gazebo/Grey</name>
            </script>
            <ambient>0.262745 0.262745 0.262745 1</ambient>
          </material>
          <meta>
            <layer>0</layer>
          </meta>
        </visual>
        <pose frame=''>1e-06 5.94223 0 0 -0 0</pose>
        <self_collide>0</self_collide>
        <kinematic>0</kinematic>
      </link>
      <link name='Wall_11'>
        <collision name='Wall_11_Collision'>
          <geometry>
            <box>
              <size>2.5 0.15 2.5</size>
            </box>
          </geometry>
          <pose frame=''>0 0 1.25 0 -0 0</pose>
          <max_contacts>10</max_contacts>
          <surface>
            <contact>
              <ode/>
            </contact>
            <bounce/>
            <friction>
              <torsional>
                <ode/>
              </torsional>
              <ode/>
            </friction>
          </surface>
        </collision>
        <visual name='Wall_11_Visual'>
          <pose frame=''>0 0 1.25 0 -0 0</pose>
          <geometry>
            <box>
              <size>2.5 0.15 2.5</size>
            </box>
          </geometry>
          <material>
            <script>
              <uri>file://media/materials/scripts/gazebo.material</uri>
              <name>Gazebo/Wood</name>
            </script>
            <ambient>1 1 1 1</ambient>
          </material>
          <meta>
            <layer>0</layer>
          </meta>
        </visual>
        <pose frame=''>-4.67255 3.32291 0 0 -0 0</pose>
        <self_collide>0</self_collide>
        <kinematic>0</kinematic>
      </link>
      <link name='Wall_13'>
        <collision name='Wall_13_Collision'>
          <geometry>
            <box>
              <size>2.75 0.15 2.5</size>
            </box>
          </geometry>
          <pose frame=''>0 0 1.25 0 -0 0</pose>
          <max_contacts>10</max_contacts>
          <surface>
            <contact>
              <ode/>
            </contact>
            <bounce/>
            <friction>
              <torsional>
                <ode/>
              </torsional>
              <ode/>
            </friction>
          </surface>
        </collision>
        <visual name='Wall_13_Visual'>
          <pose frame=''>0 0 1.25 0 -0 0</pose>
          <geometry>
            <box>
              <size>2.75 0.15 2.5</size>
            </box>
          </geometry>
          <material>
            <script>
              <uri>file://media/materials/scripts/gazebo.material</uri>
              <name>Gazebo/Wood</name>
            </script>
            <ambient>1 1 1 1</ambient>
          </material>
          <meta>
            <layer>0</layer>
          </meta>
        </visual>
        <pose frame=''>-2.38952 4.56971 0 0 -0 1.5708</pose>
        <self_collide>0</self_collide>
        <kinematic>0</kinematic>
      </link>
      <link name='Wall_15'>
        <collision name='Wall_15_Collision'>
          <geometry>
            <box>
              <size>2.75 0.15 2.5</size>
            </box>
          </geometry>
          <pose frame=''>0 0 1.25 0 -0 0</pose>
          <max_contacts>10</max_contacts>
          <surface>
            <contact>
              <ode/>
            </contact>
            <bounce/>
            <friction>
              <torsional>
                <ode/>
              </torsional>
              <ode/>
            </friction>
          </surface>
        </collision>
        <visual name='Wall_15_Visual'>
          <pose frame=''>0 0 1.25 0 -0 0</pose>
          <geometry>
            <box>
              <size>2.75 0.15 2.5</size>
            </box>
          </geometry>
          <material>
            <script>
              <uri>file://media/materials/scripts/gazebo.material</uri>
              <name>Gazebo/Wood</name>
            </script>
            <ambient>1 1 1 1</ambient>
          </material>
          <meta>
            <layer>0</layer>
          </meta>
        </visual>
        <pose frame=''>2.24053 4.63322 0 0 0 -1.5708</pose>
        <self_collide>0</self_collide>
        <kinematic>0</kinematic>
      </link>
      <link name='Wall_17'>
        <collision name='Wall_17_Collision'>
          <geometry>
            <box>
              <size>2.5 0.15 2.5</size>
            </box>
          </geometry>
          <pose frame=''>0 0 1.25 0 -0 0</pose>
          <max_contacts>10</max_contacts>
          <surface>
            <contact>
              <ode/>
            </contact>
            <bounce/>
            <friction>
              <torsional>
                <ode/>
              </torsional>
              <ode/>
            </friction>
          </surface>
        </collision>
        <visual name='Wall_17_Visual'>
          <pose frame=''>0 0 1.25 0 -0 0</pose>
          <geometry>
            <box>
              <size>2.5 0.15 2.5</size>
            </box>
          </geometry>
          <material>
            <script>
              <uri>file://media/materials/scripts/gazebo.material</uri>
              <name>Gazebo/Wood</name>
            </script>
            <ambient>1 1 1 1</ambient>
          </material>
          <meta>
            <layer>0</layer>
          </meta>
        </visual>
        <pose frame=''>4.58323 3.33305 0 0 -0 0</pose>
        <self_collide>0</self_collide>
        <kinematic>0</kinematic>
      </link>
      <link name='Wall_20'>
        <collision name='Wall_20_Collision'>
          <geometry>
            <box>
              <size>2.5 0.15 2.5</size>
            </box>
          </geometry>
          <pose frame=''>0 0 1.25 0 -0 0</pose>
          <max_contacts>10</max_contacts>
          <surface>
            <contact>
              <ode/>
            </contact>
            <bounce/>
            <friction>
              <torsional>
                <ode/>
              </torsional>
              <ode/>
            </friction>
          </surface>
        </collision>
        <visual name='Wall_20_Visual'>
          <pose frame=''>0 0 1.25 0 -0 0</pose>
          <geometry>
            <box>
              <size>2.5 0.15 2.5</size>
            </box>
          </geometry>
          <material>
            <script>
              <uri>file://media/materials/scripts/gazebo.material</uri>
              <name>Gazebo/Wood</name>
            </script>
            <ambient>1 1 1 1</ambient>
          </material>
          <meta>
            <layer>0</layer>
          </meta>
        </visual>
        <pose frame=''>-2.34801 -4.76079 0 0 -0 1.5708</pose>
        <self_collide>0</self_collide>
        <kinematic>0</kinematic>
      </link>
      <link name='Wall_24'>
        <collision name='Wall_24_Collision'>
          <geometry>
            <box>
              <size>2.5 0.15 2.5</size>
            </box>
          </geometry>
          <pose frame=''>0 0 1.25 0 -0 0</pose>
          <max_contacts>10</max_contacts>
          <surface>
            <contact>
              <ode/>
            </contact>
            <bounce/>
            <friction>
              <torsional>
                <ode/>
              </torsional>
              <ode/>
            </friction>
          </surface>
        </collision>
        <visual name='Wall_24_Visual'>
          <pose frame=''>0 0 1.25 0 -0 0</pose>
          <geometry>
            <box>
              <size>2.5 0.15 2.5</size>
            </box>
          </geometry>
          <material>
            <script>
              <uri>file://media/materials/scripts/gazebo.material</uri>
              <name>Gazebo/Wood</name>
            </script>
            <ambient>1 1 1 1</ambient>
          </material>
          <meta>
            <layer>0</layer>
          </meta>
        </visual>
        <pose frame=''>-4.70069 -3.57481 0 0 -0 0</pose>
        <self_collide>0</self_collide>
        <kinematic>0</kinematic>
      </link>
      <link name='Wall_27'>
        <collision name='Wall_27_Collision'>
          <geometry>
            <box>
              <size>2.5 0.15 2.5</size>
            </box>
          </geometry>
          <pose frame=''>0 0 1.25 0 -0 0</pose>
          <max_contacts>10</max_contacts>
          <surface>
            <contact>
              <ode/>
            </contact>
            <bounce/>
            <friction>
              <torsional>
                <ode/>
              </torsional>
              <ode/>
            </friction>
          </surface>
        </collision>
        <visual name='Wall_27_Visual'>
          <pose frame=''>0 0 1.25 0 -0 0</pose>
          <geometry>
            <box>
              <size>2.5 0.15 2.5</size>
            </box>
          </geometry>
          <material>
            <script>
              <uri>file://media/materials/scripts/gazebo.material</uri>
              <name>Gazebo/Wood</name>
            </script>
            <ambient>1 1 1 1</ambient>
          </material>
          <meta>
            <layer>0</layer>
          </meta>
        </visual>
        <pose frame=''>2.18417 -4.76723 0 0 -0 1.5708</pose>
        <self_collide>0</self_collide>
        <kinematic>0</kinematic>
      </link>
      <link name='Wall_29'>
        <collision name='Wall_29_Collision'>
          <geometry>
            <box>
              <size>2.5 0.15 2.5</size>
            </box>
          </geometry>
          <pose frame=''>0 0 1.25 0 -0 0</pose>
          <max_contacts>10</max_contacts>
          <surface>
            <contact>
              <ode/>
            </contact>
            <bounce/>
            <friction>
              <torsional>
                <ode/>
              </torsional>
              <ode/>
            </friction>
          </surface>
        </collision>
        <visual name='Wall_29_Visual'>
          <pose frame=''>0 0 1.25 0 -0 0</pose>
          <geometry>
            <box>
              <size>2.5 0.15 2.5</size>
            </box>
          </geometry>
          <material>
            <script>
              <uri>file://media/materials/scripts/gazebo.material</uri>
              <name>Gazebo/Wood</name>
            </script>
            <ambient>1 1 1 1</ambient>
          </material>
          <meta>
            <layer>0</layer>
          </meta>
        </visual>
        <pose frame=''>4.64658 -3.62801 0 0 -0 0</pose>
        <self_collide>0</self_collide>
        <kinematic>0</kinematic>
      </link>
      <link name='Wall_5'>
        <collision name='Wall_5_Collision'>
          <geometry>
            <box>
              <size>12 0.15 2.5</size>
            </box>
          </geometry>
          <pose frame=''>0 0 1.25 0 -0 0</pose>
          <max_contacts>10</max_contacts>
          <surface>
            <contact>
              <ode/>
            </contact>
            <bounce/>
            <friction>
              <torsional>
                <ode/>
              </torsional>
              <ode/>
            </friction>
          </surface>
        </collision>
        <visual name='Wall_5_Visual'>
          <pose frame=''>0 0 1.25 0 -0 0</pose>
          <geometry>
            <box>
              <size>12 0.15 2.5</size>
            </box>
          </geometry>
          <material>
            <script>
              <uri>file://media/materials/scripts/gazebo.material</uri>
              <name>Gazebo/Grey</name>
            </script>
            <ambient>0.262745 0.262745 0.262745 1</ambient>
          </material>
          <meta>
            <layer>0</layer>
          </meta>
        </visual>
        <pose frame=''>5.925 0.017226 0 0 0 -1.5708</pose>
        <self_collide>0</self_collide>
        <kinematic>0</kinematic>
      </link>
      <link name='Wall_6'>
        <collision name='Wall_6_Collision'>
          <geometry>
            <box>
              <size>12 0.15 2.5</size>
            </box>
          </geometry>
          <pose frame=''>0 0 1.25 0 -0 0</pose>
          <max_contacts>10</max_contacts>
          <surface>
            <contact>
              <ode/>
            </contact>
            <bounce/>
            <friction>
              <torsional>
                <ode/>
              </torsional>
              <ode/>
            </friction>
          </surface>
        </collision>
        <visual name='Wall_6_Visual'>
          <pose frame=''>0 0 1.25 0 -0 0</pose>
          <geometry>
            <box>
              <size>12 0.15 2.5</size>
            </box>
          </geometry>
          <material>
            <script>
              <uri>file://media/materials/scripts/gazebo.material</uri>
              <name>Gazebo/Grey</name>
            </script>
            <ambient>0.262745 0.262745 0.262745 1</ambient>
          </material>
          <meta>
            <layer>0</layer>
          </meta>
        </visual>
        <pose frame=''>1e-06 -5.90777 0 0 -0 3.14159</pose>
        <self_collide>0</self_collide>
        <kinematic>0</kinematic>
      </link>
      <link name='Wall_7'>
        <collision name='Wall_7_Collision'>
          <geometry>
            <box>
              <size>12 0.15 2.5</size>
            </box>
          </geometry>
          <pose frame=''>0 0 1.25 0 -0 0</pose>
          <max_contacts>10</max_contacts>
          <surface>
            <contact>
              <ode/>
            </contact>
            <bounce/>
            <friction>
              <torsional>
                <ode/>
              </torsional>
              <ode/>
            </friction>
          </surface>
        </collision>
        <visual name='Wall_7_Visual'>
          <pose frame=''>0 0 1.25 0 -0 0</pose>
          <geometry>
            <box>
              <size>12 0.15 2.5</size>
            </box>
          </geometry>
          <material>
            <script>
              <uri>file://media/materials/scripts/gazebo.material</uri>
              <name>Gazebo/Grey</name>
            </script>
            <ambient>0.262745 0.262745 0.262745 1</ambient>
          </material>
          <meta>
            <layer>0</layer>
          </meta>
        </visual>
        <pose frame=''>-5.925 0.017226 0 0 -0 1.5708</pose>
        <self_collide>0</self_collide>
        <kinematic>0</kinematic>
      </link>
      <static>1</static>
    </model>
    <state world_name='default'>
      <sim_time>18 730000000</sim_time>
      <real_time>17 94382449</real_time>
      <wall_time>1746333627 283740361</wall_time>
      <iterations>18730</iterations>
      <model name='ground_plane'>
        <pose frame=''>0 0 0 0 -0 0</pose>
        <scale>1 1 1</scale>
        <link name='link'>
          <pose frame=''>0 0 0 0 -0 0</pose>
          <velocity>0 0 0 0 -0 0</velocity>
          <acceleration>0 0 0 0 -0 0</acceleration>
          <wrench>0 0 0 0 -0 0</wrench>
        </link>
      </model>
      <model name='hammer'>
        <pose frame=''>7.85873 1.38078 0 0 -0 0</pose>
        <scale>1 1 1</scale>
        <link name='link'>
          <pose frame=''>7.85873 1.38078 0 0 -0 0</pose>
          <velocity>0 0 0 0 -0 0</velocity>
          <acceleration>0 0 0 0 -0 0</acceleration>
          <wrench>0 0 0 0 -0 0</wrench>
        </link>
      </model>
      <model name='mybuilding'>
        <pose frame=''>2.20281 -1.08322 0 0 -0 0</pose>
        <scale>1 1 1</scale>
        <link name='Wall_0'>
          <pose frame=''>2.20281 4.85901 0 0 -0 0</pose>
          <velocity>0 0 0 0 -0 0</velocity>
          <acceleration>0 0 0 0 -0 0</acceleration>
          <wrench>0 0 0 0 -0 0</wrench>
        </link>
        <link name='Wall_11'>
          <pose frame=''>-2.46974 2.23969 0 0 -0 0</pose>
          <velocity>0 0 0 0 -0 0</velocity>
          <acceleration>0 0 0 0 -0 0</acceleration>
          <wrench>0 0 0 0 -0 0</wrench>
        </link>
        <link name='Wall_13'>
          <pose frame=''>-0.186711 3.48649 0 0 -0 1.5708</pose>
          <velocity>0 0 0 0 -0 0</velocity>
          <acceleration>0 0 0 0 -0 0</acceleration>
          <wrench>0 0 0 0 -0 0</wrench>
        </link>
        <link name='Wall_15'>
          <pose frame=''>4.44334 3.55 0 0 0 -1.5708</pose>
          <velocity>0 0 0 0 -0 0</velocity>
          <acceleration>0 0 0 0 -0 0</acceleration>
          <wrench>0 0 0 0 -0 0</wrench>
        </link>
        <link name='Wall_17'>
          <pose frame=''>6.78604 2.24983 0 0 -0 0</pose>
          <velocity>0 0 0 0 -0 0</velocity>
          <acceleration>0 0 0 0 -0 0</acceleration>
          <wrench>0 0 0 0 -0 0</wrench>
        </link>
        <link name='Wall_20'>
          <pose frame=''>-0.145201 -5.84401 0 0 -0 1.5708</pose>
          <velocity>0 0 0 0 -0 0</velocity>
          <acceleration>0 0 0 0 -0 0</acceleration>
          <wrench>0 0 0 0 -0 0</wrench>
        </link>
        <link name='Wall_24'>
          <pose frame=''>-2.49788 -4.65803 0 0 -0 0</pose>
          <velocity>0 0 0 0 -0 0</velocity>
          <acceleration>0 0 0 0 -0 0</acceleration>
          <wrench>0 0 0 0 -0 0</wrench>
        </link>
        <link name='Wall_27'>
          <pose frame=''>4.38698 -5.85045 0 0 -0 1.5708</pose>
          <velocity>0 0 0 0 -0 0</velocity>
          <acceleration>0 0 0 0 -0 0</acceleration>
          <wrench>0 0 0 0 -0 0</wrench>
        </link>
        <link name='Wall_29'>
          <pose frame=''>6.84939 -4.71123 0 0 -0 0</pose>
          <velocity>0 0 0 0 -0 0</velocity>
          <acceleration>0 0 0 0 -0 0</acceleration>
          <wrench>0 0 0 0 -0 0</wrench>
        </link>
        <link name='Wall_5'>
          <pose frame=''>8.12781 -1.066 0 0 0 -1.5708</pose>
          <velocity>0 0 0 0 -0 0</velocity>
          <acceleration>0 0 0 0 -0 0</acceleration>
          <wrench>0 0 0 0 -0 0</wrench>
        </link>
        <link name='Wall_6'>
          <pose frame=''>2.20281 -6.99099 0 0 -0 3.14159</pose>
          <velocity>0 0 0 0 -0 0</velocity>
          <acceleration>0 0 0 0 -0 0</acceleration>
          <wrench>0 0 0 0 -0 0</wrench>
        </link>
        <link name='Wall_7'>
          <pose frame=''>-3.72219 -1.066 0 0 -0 1.5708</pose>
          <velocity>0 0 0 0 -0 0</velocity>
          <acceleration>0 0 0 0 -0 0</acceleration>
          <wrench>0 0 0 0 -0 0</wrench>
        </link>
      </model>
      <model name='myrobot1'>
        <pose frame=''>3.27227 0.965902 0.256741 0 -0 0</pose>
        <scale>1 1 1</scale>
        <model name='robot1'>
          <pose frame=''>3.27227 0.965902 0.256741 0 -0 0</pose>
          <scale>1 1 1</scale>
          <link name='link_0'>
            <pose frame=''>3.27227 0.965902 0.256741 0 -0 0</pose>
            <velocity>0 0 0 0 -0 0</velocity>
            <acceleration>0 0 0 0 -0 0</acceleration>
            <wrench>0 0 0 0 -0 0</wrench>
          </link>
          <link name='link_2'>
            <pose frame=''>3.27227 0.415883 0.256741 1.5707 -0 0</pose>
            <velocity>0 0 0 0 -0 0</velocity>
            <acceleration>0 0 0 0 -0 0</acceleration>
            <wrench>0 0 0 0 -0 0</wrench>
          </link>
          <link name='link_2_clone'>
            <pose frame=''>3.27227 1.51592 0.256741 1.5707 -0 0</pose>
            <velocity>0 0 0 0 -0 0</velocity>
            <acceleration>0 0 0 0 -0 0</acceleration>
            <wrench>0 0 0 0 -0 0</wrench>
          </link>
        </model>
      </model>
      <model name='myrobot1_0'>
        <pose frame=''>0.855103 -3.4237 0.439542 0 -0 0</pose>
        <scale>1 1 1</scale>
        <model name='robot1'>
          <pose frame=''>0.855105 -3.4237 0.439542 0 -0 0</pose>
          <scale>1 1 1</scale>
          <link name='link_0'>
            <pose frame=''>0.855105 -3.4237 0.439542 0 -0 0</pose>
            <velocity>0 0 0 0 -0 0</velocity>
            <acceleration>0 0 0 0 -0 0</acceleration>
            <wrench>0 0 0 0 -0 0</wrench>
          </link>
          <link name='link_2'>
            <pose frame=''>0.855105 -3.97372 0.439542 1.5707 -0 0</pose>
            <velocity>0 0 0 0 -0 0</velocity>
            <acceleration>0 0 0 0 -0 0</acceleration>
            <wrench>0 0 0 0 -0 0</wrench>
          </link>
          <link name='link_2_clone'>
            <pose frame=''>0.855105 -2.87368 0.439542 1.5707 -0 0</pose>
            <velocity>0 0 0 0 -0 0</velocity>
            <acceleration>0 0 0 0 -0 0</acceleration>
            <wrench>0 0 0 0 -0 0</wrench>
          </link>
        </model>
      </model>
      <model name='postbox'>
        <pose frame=''>7.5063 -3.95604 0 0 -0 0</pose>
        <scale>1 1 1</scale>
        <link name='link'>
          <pose frame=''>7.5063 -3.95604 0 0 -0 0</pose>
          <velocity>0 0 0 0 -0 0</velocity>
          <acceleration>0 0 0 0 -0 0</acceleration>
          <wrench>0 0 0 0 -0 0</wrench>
        </link>
      </model>
      <model name='simple_arm_gripper'>
        <pose frame=''>-2.86725 -1.63559 -0.000136 -0.000279 -4e-06 -0.017938</pose>
        <scale>1 1 1</scale>
        <link name='simple_arm::arm_base'>
          <pose frame=''>-2.86725 -1.63559 -0.000136 -0.000279 -4e-06 -0.017938</pose>
          <velocity>-0.000222 -0.000497 -0.037231 -0.095364 0.001169 0.000391</velocity>
          <acceleration>-0.45613 -0.635043 0.496568 -0.644916 -0.468284 0.032521</acceleration>
          <wrench>-46.0691 -64.1393 50.1534 0 -0 0</wrench>
        </link>
        <link name='simple_arm::arm_elbow_pan'>
          <pose frame=''>-2.27778 -0.766378 1.09968 -0.000177 -1.9e-05 -0.018676</pose>
          <velocity>0.024743 0.089386 -0.061572 -0.024233 -0.030474 -0.142934</velocity>
          <acceleration>19.2012 68.4165 -56.1615 1.70012 0.99314 1.42231</acceleration>
          <wrench>23.0414 82.0997 -67.3938 0 -0 0</wrench>
        </link>
        <link name='simple_arm::arm_shoulder_pan'>
          <pose frame=''>-2.86725 -1.63529 1.09987 -0.00023 0.000221 0.974695</pose>
          <velocity>-0.000744 0.105035 -0.030916 -0.118372 -0.03626 -0.046829</velocity>
          <acceleration>2.78004 102.643 -37.9706 2.8398 -0.77543 0.310855</acceleration>
          <wrench>3.05804 112.907 -41.7677 0 -0 0</wrench>
        </link>
        <link name='simple_arm::arm_wrist_lift'>
          <pose frame=''>-1.72788 -0.776765 0.250683 -0.000159 6.5e-05 -0.018626</pose>
          <velocity>0.033752 -0.007033 -0.008044 -0.014855 0.018118 -0.117524</velocity>
          <acceleration>33.7523 -7.03348 -8.04417 -2.2973 -0.749704 1.87308</acceleration>
          <wrench>3.37523 -0.703348 -0.804417 0 -0 0</wrench>
        </link>
        <link name='simple_arm::arm_wrist_roll'>
          <pose frame=''>-1.7279 -0.77677 0.200683 6.9e-05 -0.000102 -2.73342</pose>
          <velocity>0.026376 -0.00667 -0.008019 -0.006436 0.019659 0.02042</velocity>
          <acceleration>26.3758 -6.66968 -8.01917 -0.151206 0.811032 1.5853</acceleration>
          <wrench>2.63758 -0.666968 -0.801917 0 -0 0</wrench>
        </link>
        <link name='simple_gripper::left_finger'>
          <pose frame=''>-1.92391 -1.07937 0.251185 3.9e-05 -7e-06 2.76429</pose>
          <velocity>0.002609 0.000824 -0.009698 0.001802 -0.002229 -0.000366</velocity>
          <acceleration>2.60945 0.824184 -9.69814 -1.33966 -0.912717 2.77589</acceleration>
          <wrench>0.260945 0.082418 -0.969814 0 -0 0</wrench>
        </link>
        <link name='simple_gripper::left_finger_tip'>
          <pose frame=''>-2.10084 -1.26483 0.251195 -3.3e-05 -2.3e-05 -1.16271</pose>
          <velocity>0.002753 0.000837 -0.010425 0.00179 -0.002263 -1.6e-05</velocity>
          <acceleration>2.75344 0.83736 -10.4245 -1.35194 -0.878358 3.1254</acceleration>
          <wrench>1.37672 0.41868 -5.21227 0 -0 0</wrench>
        </link>
        <link name='simple_gripper::palm'>
          <pose frame=''>-1.9115 -0.856112 0.251177 2.3e-05 -3.3e-05 -2.73342</pose>
          <velocity>0.003164 0.000774 -0.009279 0.0018 -0.002234 -0.000378</velocity>
          <acceleration>3.16398 0.774457 -9.2785 -1.34196 -0.907336 2.76372</acceleration>
          <wrench>1.58199 0.387229 -4.63925 0 -0 0</wrench>
        </link>
        <link name='simple_gripper::right_finger'>
          <pose frame=''>-2.08268 -0.712242 0.251176 -8e-06 -3.9e-05 -1.94799</pose>
          <velocity>0.003069 0.00079 -0.009356 0.00185 -0.002072 7.9e-05</velocity>
          <acceleration>3.0688 0.789713 -9.35606 -1.29174 -1.06939 -3.06288</acceleration>
          <wrench>0.30688 0.078971 -0.935606 0 -0 0</wrench>
        </link>
        <link name='simple_gripper::right_finger_tip'>
          <pose frame=''>-2.33899 -0.71414 0.251182 -3.3e-05 -2.2e-05 -1.16271</pose>
          <velocity>0.002832 0.000803 -0.009832 0.001884 -0.001949 -4e-06</velocity>
          <acceleration>2.83186 0.802681 -9.83218 -1.25737 -1.19234 3.13772</acceleration>
          <wrench>0.283186 0.080268 -0.983218 0 -0 0</wrench>
        </link>
        <link name='simple_gripper::riser'>
          <pose frame=''>-1.77382 -0.796557 0.700683 2.4e-05 -3.3e-05 -2.73342</pose>
          <velocity>0.002411 -0.000136 -0.009835 0.001639 -0.002722 -0.000395</velocity>
          <acceleration>2.41117 -0.135663 -9.83533 -1.50281 -0.419423 2.74651</acceleration>
          <wrench>24.1117 -1.35663 -98.3533 0 -0 0</wrench>
        </link>
      </model>
      <light name='user_directional_light_0'>
        <pose frame=''>1.41941 -1.71758 1 0 -0 0</pose>
      </light>
    </state>
    <model name='simple_arm_gripper'>
      <link name='simple_arm::arm_base'>
        <inertial>
          <pose frame=''>0 0 0.00099 0 -0 0</pose>
          <inertia>
            <ixx>1.11</ixx>
            <ixy>0</ixy>
            <ixz>0</ixz>
            <iyy>100.11</iyy>
            <iyz>0</iyz>
            <izz>1.01</izz>
          </inertia>
          <mass>101</mass>
        </inertial>
        <collision name='arm_base_geom'>
          <pose frame=''>0 0 0.05 0 -0 0</pose>
          <geometry>
            <box>
              <size>1 1 0.1</size>
            </box>
          </geometry>
          <max_contacts>10</max_contacts>
          <surface>
            <contact>
              <ode/>
            </contact>
            <bounce/>
            <friction>
              <torsional>
                <ode/>
              </torsional>
              <ode/>
            </friction>
          </surface>
        </collision>
        <visual name='arm_base_geom_visual'>
          <pose frame=''>0 0 0.05 0 -0 0</pose>
          <geometry>
            <box>
              <size>1 1 0.1</size>
            </box>
          </geometry>
          <material>
            <script>
              <uri>file://media/materials/scripts/gazebo.material</uri>
              <name>Gazebo/Blue</name>
            </script>
          </material>
        </visual>
        <collision name='arm_base_geom_arm_trunk'>
          <pose frame=''>0 0 0.6 0 -0 0</pose>
          <geometry>
            <cylinder>
              <radius>0.05</radius>
              <length>1</length>
            </cylinder>
          </geometry>
          <max_contacts>10</max_contacts>
          <surface>
            <contact>
              <ode/>
            </contact>
            <bounce/>
            <friction>
              <torsional>
                <ode/>
              </torsional>
              <ode/>
            </friction>
          </surface>
        </collision>
        <visual name='arm_base_geom_arm_trunk_visual'>
          <pose frame=''>0 0 0.6 0 -0 0</pose>
          <geometry>
            <cylinder>
              <radius>0.05</radius>
              <length>1</length>
            </cylinder>
          </geometry>
          <material>
            <script>
              <uri>file://media/materials/scripts/gazebo.material</uri>
              <name>Gazebo/Red</name>
            </script>
          </material>
        </visual>
        <pose frame=''>0 0 0 0 -0 0</pose>
        <self_collide>0</self_collide>
        <kinematic>0</kinematic>
      </link>
      <link name='simple_arm::arm_shoulder_pan'>
        <pose frame=''>0 0 1.1 0 -0 0</pose>
        <inertial>
          <pose frame=''>0.045455 0 0 0 -0 0</pose>
          <inertia>
            <ixx>0.011</ixx>
            <ixy>0</ixy>
            <ixz>0</ixz>
            <iyy>0.0225</iyy>
            <iyz>0</iyz>
            <izz>0.0135</izz>
          </inertia>
          <mass>1.1</mass>
        </inertial>
        <collision name='arm_shoulder_pan_geom'>
          <pose frame=''>0 0 0.05 0 -0 0</pose>
          <geometry>
            <cylinder>
              <radius>0.05</radius>
              <length>0.1</length>
            </cylinder>
          </geometry>
          <max_contacts>10</max_contacts>
          <surface>
            <contact>
              <ode/>
            </contact>
            <bounce/>
            <friction>
              <torsional>
                <ode/>
              </torsional>
              <ode/>
            </friction>
          </surface>
        </collision>
        <visual name='arm_shoulder_pan_geom_visual'>
          <pose frame=''>0 0 0.05 0 -0 0</pose>
          <geometry>
            <cylinder>
              <radius>0.05</radius>
              <length>0.1</length>
            </cylinder>
          </geometry>
          <material>
            <script>
              <uri>file://media/materials/scripts/gazebo.material</uri>
              <name>Gazebo/Yellow</name>
            </script>
          </material>
        </visual>
        <collision name='arm_shoulder_pan_geom_arm_shoulder'>
          <pose frame=''>0.55 0 0.05 0 -0 0</pose>
          <geometry>
            <box>
              <size>1 0.05 0.1</size>
            </box>
          </geometry>
          <max_contacts>10</max_contacts>
          <surface>
            <contact>
              <ode/>
            </contact>
            <bounce/>
            <friction>
              <torsional>
                <ode/>
              </torsional>
              <ode/>
            </friction>
          </surface>
        </collision>
        <visual name='arm_shoulder_pan_geom_arm_shoulder_visual'>
          <pose frame=''>0.55 0 0.05 0 -0 0</pose>
          <geometry>
            <box>
              <size>1 0.05 0.1</size>
            </box>
          </geometry>
          <material>
            <script>
              <uri>file://media/materials/scripts/gazebo.material</uri>
              <name>Gazebo/Yellow</name>
            </script>
          </material>
        </visual>
        <self_collide>0</self_collide>
        <kinematic>0</kinematic>
      </link>
      <link name='simple_arm::arm_elbow_pan'>
        <pose frame=''>1.05 0 1.1 0 -0 0</pose>
        <inertial>
          <pose frame=''>0.0875 0 0.083333 0 -0 0</pose>
          <inertia>
            <ixx>0.031</ixx>
            <ixy>0</ixy>
            <ixz>0.005</ixz>
            <iyy>0.07275</iyy>
            <iyz>0</iyz>
            <izz>0.04475</izz>
          </inertia>
          <mass>1.2</mass>
        </inertial>
        <collision name='arm_elbow_pan_geom'>
          <pose frame=''>0 0 0.1 0 -0 0</pose>
          <geometry>
            <cylinder>
              <radius>0.05</radius>
              <length>0.2</length>
            </cylinder>
          </geometry>
          <max_contacts>10</max_contacts>
          <surface>
            <contact>
              <ode/>
            </contact>
            <bounce/>
            <friction>
              <torsional>
                <ode/>
              </torsional>
              <ode/>
            </friction>
          </surface>
        </collision>
        <visual name='arm_elbow_pan_geom_visual'>
          <pose frame=''>0 0 0.1 0 -0 0</pose>
          <geometry>
            <cylinder>
              <radius>0.05</radius>
              <length>0.2</length>
            </cylinder>
          </geometry>
          <material>
            <script>
              <uri>file://media/materials/scripts/gazebo.material</uri>
              <name>Gazebo/Red</name>
            </script>
          </material>
        </visual>
        <collision name='arm_elbow_pan_geom_arm_elbow'>
          <pose frame=''>0.3 0 0.15 0 -0 0</pose>
          <geometry>
            <box>
              <size>0.5 0.03 0.1</size>
            </box>
          </geometry>
          <max_contacts>10</max_contacts>
          <surface>
            <contact>
              <ode/>
            </contact>
            <bounce/>
            <friction>
              <torsional>
                <ode/>
              </torsional>
              <ode/>
            </friction>
          </surface>
        </collision>
        <visual name='arm_elbow_pan_geom_arm_elbow_visual'>
          <pose frame=''>0.3 0 0.15 0 -0 0</pose>
          <geometry>
            <box>
              <size>0.5 0.03 0.1</size>
            </box>
          </geometry>
          <material>
            <script>
              <uri>file://media/materials/scripts/gazebo.material</uri>
              <name>Gazebo/Yellow</name>
            </script>
          </material>
        </visual>
        <collision name='arm_elbow_pan_geom_arm_wrist'>
          <pose frame=''>0.55 0 0.15 0 -0 0</pose>
          <geometry>
            <cylinder>
              <radius>0.05</radius>
              <length>0.3</length>
            </cylinder>
          </geometry>
          <max_contacts>10</max_contacts>
          <surface>
            <contact>
              <ode/>
            </contact>
            <bounce/>
            <friction>
              <torsional>
                <ode/>
              </torsional>
              <ode/>
            </friction>
          </surface>
        </collision>
        <visual name='arm_elbow_pan_geom_arm_wrist_visual'>
          <pose frame=''>0.55 0 0.15 0 -0 0</pose>
          <geometry>
            <cylinder>
              <radius>0.05</radius>
              <length>0.3</length>
            </cylinder>
          </geometry>
          <material>
            <script>
              <uri>file://media/materials/scripts/gazebo.material</uri>
              <name>Gazebo/Red</name>
            </script>
          </material>
        </visual>
        <self_collide>0</self_collide>
        <kinematic>0</kinematic>
      </link>
      <link name='simple_arm::arm_wrist_lift'>
        <pose frame=''>1.6 0 1.05 0 -0 0</pose>
        <inertial>
          <pose frame=''>0 0 0 0 -0 0</pose>
          <inertia>
            <ixx>0.01</ixx>
            <ixy>0</ixy>
            <ixz>0</ixz>
            <iyy>0.01</iyy>
            <iyz>0</iyz>
            <izz>0.001</izz>
          </inertia>
          <mass>0.1</mass>
        </inertial>
        <collision name='arm_wrist_lift_geom'>
          <pose frame=''>0 0 0.5 0 -0 0</pose>
          <geometry>
            <cylinder>
              <radius>0.03</radius>
              <length>1</length>
            </cylinder>
          </geometry>
          <max_contacts>10</max_contacts>
          <surface>
            <contact>
              <ode/>
            </contact>
            <bounce/>
            <friction>
              <torsional>
                <ode/>
              </torsional>
              <ode/>
            </friction>
          </surface>
        </collision>
        <visual name='arm_wrist_lift_geom_visual'>
          <pose frame=''>0 0 0.5 0 -0 0</pose>
          <geometry>
            <cylinder>
              <radius>0.03</radius>
              <length>1</length>
            </cylinder>
          </geometry>
          <material>
            <script>
              <uri>file://media/materials/scripts/gazebo.material</uri>
              <name>Gazebo/Yellow</name>
            </script>
          </material>
        </visual>
        <self_collide>0</self_collide>
        <kinematic>0</kinematic>
      </link>
      <link name='simple_arm::arm_wrist_roll'>
        <pose frame=''>1.6 0 1 0 -0 0</pose>
        <inertial>
          <pose frame=''>0 0 0 0 -0 0</pose>
          <inertia>
            <ixx>0.01</ixx>
            <ixy>0</ixy>
            <ixz>0</ixz>
            <iyy>0.01</iyy>
            <iyz>0</iyz>
            <izz>0.001</izz>
          </inertia>
          <mass>0.1</mass>
        </inertial>
        <collision name='arm_wrist_roll_geom'>
          <pose frame=''>0 0 0.025 0 -0 0</pose>
          <geometry>
            <cylinder>
              <radius>0.05</radius>
              <length>0.05</length>
            </cylinder>
          </geometry>
          <max_contacts>10</max_contacts>
          <surface>
            <contact>
              <ode/>
            </contact>
            <bounce/>
            <friction>
              <torsional>
                <ode/>
              </torsional>
              <ode/>
            </friction>
          </surface>
        </collision>
        <visual name='arm_wrist_roll_geom_visual'>
          <pose frame=''>0 0 0.025 0 -0 0</pose>
          <geometry>
            <cylinder>
              <radius>0.05</radius>
              <length>0.05</length>
            </cylinder>
          </geometry>
          <material>
            <script>
              <uri>file://media/materials/scripts/gazebo.material</uri>
              <name>Gazebo/Red</name>
            </script>
          </material>
        </visual>
        <self_collide>0</self_collide>
        <kinematic>0</kinematic>
      </link>
      <joint name='simple_arm::arm_shoulder_pan_joint' type='revolute'>
        <parent>simple_arm::arm_base</parent>
        <child>simple_arm::arm_shoulder_pan</child>
        <axis>
          <dynamics>
            <damping>1</damping>
            <friction>0</friction>
            <spring_reference>0</spring_reference>
            <spring_stiffness>0</spring_stiffness>
          </dynamics>
          <xyz>0 0 1</xyz>
          <use_parent_model_frame>1</use_parent_model_frame>
          <limit>
            <lower>-1e+16</lower>
            <upper>1e+16</upper>
          </limit>
        </axis>
      </joint>
      <joint name='simple_arm::arm_elbow_pan_joint' type='revolute'>
        <parent>simple_arm::arm_shoulder_pan</parent>
        <child>simple_arm::arm_elbow_pan</child>
        <axis>
          <dynamics>
            <damping>1</damping>
            <friction>0</friction>
            <spring_reference>0</spring_reference>
            <spring_stiffness>0</spring_stiffness>
          </dynamics>
          <xyz>0 0 1</xyz>
          <use_parent_model_frame>1</use_parent_model_frame>
          <limit>
            <lower>-1e+16</lower>
            <upper>1e+16</upper>
          </limit>
        </axis>
      </joint>
      <joint name='simple_arm::arm_wrist_lift_joint' type='prismatic'>
        <parent>simple_arm::arm_elbow_pan</parent>
        <child>simple_arm::arm_wrist_lift</child>
        <axis>
          <dynamics>
            <damping>1</damping>
            <friction>0</friction>
            <spring_reference>0</spring_reference>
            <spring_stiffness>0</spring_stiffness>
          </dynamics>
          <limit>
            <lower>-0.8</lower>
            <upper>0.1</upper>
          </limit>
          <xyz>0 0 1</xyz>
          <use_parent_model_frame>1</use_parent_model_frame>
        </axis>
      </joint>
      <joint name='simple_arm::arm_wrist_roll_joint' type='revolute'>
        <parent>simple_arm::arm_wrist_lift</parent>
        <child>simple_arm::arm_wrist_roll</child>
        <axis>
          <dynamics>
            <damping>1</damping>
            <friction>0</friction>
            <spring_reference>0</spring_reference>
            <spring_stiffness>0</spring_stiffness>
          </dynamics>
          <limit>
            <lower>-2.99999</lower>
            <upper>2.99999</upper>
          </limit>
          <xyz>0 0 1</xyz>
          <use_parent_model_frame>1</use_parent_model_frame>
        </axis>
      </joint>
      <link name='simple_gripper::riser'>
        <pose frame=''>1.65 0 1.5 0 -0 0</pose>
        <inertial>
          <mass>10</mass>
          <inertia>
            <ixx>1</ixx>
            <ixy>0</ixy>
            <ixz>0</ixz>
            <iyy>1</iyy>
            <iyz>0</iyz>
            <izz>1</izz>
          </inertia>
        </inertial>
        <collision name='collision'>
          <geometry>
            <box>
              <size>0.05 0.05 1</size>
            </box>
          </geometry>
          <surface>
            <contact>
              <ode>
                <max_vel>0</max_vel>
              </ode>
            </contact>
            <bounce/>
            <friction>
              <torsional>
                <ode/>
              </torsional>
              <ode/>
            </friction>
          </surface>
          <max_contacts>10</max_contacts>
        </collision>
        <visual name='visual'>
          <geometry>
            <box>
              <size>0.05 0.05 1</size>
            </box>
          </geometry>
        </visual>
        <self_collide>0</self_collide>
        <kinematic>0</kinematic>
      </link>
      <link name='simple_gripper::palm'>
        <pose frame=''>1.8 0 1.05 0 -0 0</pose>
        <inertial>
          <mass>0.5</mass>
          <inertia>
            <ixx>1</ixx>
            <ixy>0</ixy>
            <ixz>0</ixz>
            <iyy>1</iyy>
            <iyz>0</iyz>
            <izz>1</izz>
          </inertia>
        </inertial>
        <collision name='collision'>
          <geometry>
            <box>
              <size>0.1 0.2 0.1</size>
            </box>
          </geometry>
          <surface>
            <contact>
              <ode>
                <max_vel>0</max_vel>
              </ode>
            </contact>
            <bounce/>
            <friction>
              <torsional>
                <ode/>
              </torsional>
              <ode/>
            </friction>
          </surface>
          <max_contacts>10</max_contacts>
        </collision>
        <visual name='visual'>
          <geometry>
            <box>
              <size>0.1 0.2 0.1</size>
            </box>
          </geometry>
        </visual>
        <self_collide>0</self_collide>
        <kinematic>0</kinematic>
      </link>
      <link name='simple_gripper::left_finger'>
        <pose frame=''>1.9 0.2 1.05 0 0 -0.78539</pose>
        <inertial>
          <mass>0.1</mass>
          <inertia>
            <ixx>1</ixx>
            <ixy>0</ixy>
            <ixz>0</ixz>
            <iyy>1</iyy>
            <iyz>0</iyz>
            <izz>1</izz>
          </inertia>
        </inertial>
        <collision name='collision'>
          <geometry>
            <box>
              <size>0.1 0.3 0.1</size>
            </box>
          </geometry>
          <surface>
            <friction>
              <ode>
                <mu>0.1</mu>
                <mu2>0</mu2>
              </ode>
              <torsional>
                <ode/>
              </torsional>
            </friction>
            <contact>
              <ode>
                <max_vel>0</max_vel>
              </ode>
            </contact>
            <bounce/>
          </surface>
          <max_contacts>10</max_contacts>
        </collision>
        <visual name='visual'>
          <geometry>
            <box>
              <size>0.1 0.3 0.1</size>
            </box>
          </geometry>
        </visual>
        <self_collide>0</self_collide>
        <kinematic>0</kinematic>
      </link>
      <link name='simple_gripper::left_finger_tip'>
        <pose frame=''>2.136 0.3 1.05 0 -0 1.5707</pose>
        <inertial>
          <mass>0.5</mass>
          <inertia>
            <ixx>1</ixx>
            <ixy>0</ixy>
            <ixz>0</ixz>
            <iyy>1</iyy>
            <iyz>0</iyz>
            <izz>1</izz>
          </inertia>
        </inertial>
        <collision name='collision'>
          <geometry>
            <box>
              <size>0.1 0.2 0.1</size>
            </box>
          </geometry>
          <surface>
            <friction>
              <ode>
                <mu>0.1</mu>
                <mu2>0</mu2>
              </ode>
              <torsional>
                <ode/>
              </torsional>
            </friction>
            <contact>
              <ode>
                <max_vel>0</max_vel>
              </ode>
            </contact>
            <bounce/>
          </surface>
          <max_contacts>10</max_contacts>
        </collision>
        <visual name='visual'>
          <geometry>
            <box>
              <size>0.1 0.2 0.1</size>
            </box>
          </geometry>
        </visual>
        <self_collide>0</self_collide>
        <kinematic>0</kinematic>
      </link>
      <link name='simple_gripper::right_finger'>
        <pose frame=''>1.9 -0.2 1.05 0 -0 0.78539</pose>
        <inertial>
          <mass>0.1</mass>
          <inertia>
            <ixx>1</ixx>
            <ixy>0</ixy>
            <ixz>0</ixz>
            <iyy>1</iyy>
            <iyz>0</iyz>
            <izz>1</izz>
          </inertia>
        </inertial>
        <collision name='collision'>
          <geometry>
            <box>
              <size>0.1 0.3 0.1</size>
            </box>
          </geometry>
          <surface>
            <friction>
              <ode>
                <mu>0.1</mu>
                <mu2>0</mu2>
              </ode>
              <torsional>
                <ode/>
              </torsional>
            </friction>
            <contact>
              <ode>
                <max_vel>0</max_vel>
              </ode>
            </contact>
            <bounce/>
          </surface>
          <max_contacts>10</max_contacts>
        </collision>
        <visual name='visual'>
          <geometry>
            <box>
              <size>0.1 0.3 0.1</size>
            </box>
          </geometry>
        </visual>
        <self_collide>0</self_collide>
        <kinematic>0</kinematic>
      </link>
      <link name='simple_gripper::right_finger_tip'>
        <pose frame=''>2.136 -0.3 1.05 0 -0 1.5707</pose>
        <inertial>
          <mass>0.1</mass>
          <inertia>
            <ixx>1</ixx>
            <ixy>0</ixy>
            <ixz>0</ixz>
            <iyy>1</iyy>
            <iyz>0</iyz>
            <izz>1</izz>
          </inertia>
        </inertial>
        <collision name='collision'>
          <geometry>
            <box>
              <size>0.1 0.2 0.1</size>
            </box>
          </geometry>
          <surface>
            <friction>
              <ode>
                <mu>0.1</mu>
                <mu2>0</mu2>
              </ode>
              <torsional>
                <ode/>
              </torsional>
            </friction>
            <contact>
              <ode>
                <max_vel>0</max_vel>
              </ode>
            </contact>
            <bounce/>
          </surface>
          <max_contacts>10</max_contacts>
        </collision>
        <visual name='visual'>
          <geometry>
            <box>
              <size>0.1 0.2 0.1</size>
            </box>
          </geometry>
        </visual>
        <self_collide>0</self_collide>
        <kinematic>0</kinematic>
      </link>
      <joint name='simple_gripper::palm_left_finger' type='revolute'>
        <pose frame=''>0 -0.15 0 0 -0 0</pose>
        <child>simple_gripper::left_finger</child>
        <parent>simple_gripper::palm</parent>
        <axis>
          <limit>
            <lower>-0.8</lower>
            <upper>0.8</upper>
          </limit>
          <xyz>0 0 1</xyz>
          <use_parent_model_frame>1</use_parent_model_frame>
          <dynamics>
            <spring_reference>0</spring_reference>
            <spring_stiffness>0</spring_stiffness>
          </dynamics>
        </axis>
      </joint>
      <joint name='simple_gripper::left_finger_tip' type='revolute'>
        <pose frame=''>0 0.1 0 0 -0 0</pose>
        <child>simple_gripper::left_finger_tip</child>
        <parent>simple_gripper::left_finger</parent>
        <axis>
          <limit>
            <lower>-0.8</lower>
            <upper>0.8</upper>
          </limit>
          <xyz>0 0 1</xyz>
          <use_parent_model_frame>1</use_parent_model_frame>
          <dynamics>
            <spring_reference>0</spring_reference>
            <spring_stiffness>0</spring_stiffness>
          </dynamics>
        </axis>
      </joint>
      <joint name='simple_gripper::palm_right_finger' type='revolute'>
        <pose frame=''>0 0.15 0 0 -0 0</pose>
        <child>simple_gripper::right_finger</child>
        <parent>simple_gripper::palm</parent>
        <axis>
          <limit>
            <lower>-0.8</lower>
            <upper>0.8</upper>
          </limit>
          <xyz>0 0 1</xyz>
          <use_parent_model_frame>1</use_parent_model_frame>
          <dynamics>
            <spring_reference>0</spring_reference>
            <spring_stiffness>0</spring_stiffness>
          </dynamics>
        </axis>
      </joint>
      <joint name='simple_gripper::right_finger_tip' type='revolute'>
        <pose frame=''>0 0.1 0 0 -0 0</pose>
        <child>simple_gripper::right_finger_tip</child>
        <parent>simple_gripper::right_finger</parent>
        <axis>
          <limit>
            <lower>-0.8</lower>
            <upper>0.8</upper>
          </limit>
          <xyz>0 0 1</xyz>
          <use_parent_model_frame>1</use_parent_model_frame>
          <dynamics>
            <spring_reference>0</spring_reference>
            <spring_stiffness>0</spring_stiffness>
          </dynamics>
        </axis>
      </joint>
      <joint name='simple_gripper::palm_riser' type='prismatic'>
        <child>simple_gripper::palm</child>
        <parent>simple_gripper::riser</parent>
        <axis>
          <limit>
            <lower>0</lower>
            <upper>0.9</upper>
          </limit>
          <xyz>0 0 1</xyz>
          <use_parent_model_frame>1</use_parent_model_frame>
          <dynamics>
            <spring_reference>0</spring_reference>
            <spring_stiffness>0</spring_stiffness>
          </dynamics>
        </axis>
      </joint>
      <gripper name='simple_gripper'>
        <grasp_check>
          <detach_steps>40</detach_steps>
          <attach_steps>20</attach_steps>
          <min_contact_count>2</min_contact_count>
        </grasp_check>
        <gripper_link>simple_gripper::right_finger</gripper_link>
        <gripper_link>simple_gripper::right_finger_tip</gripper_link>
        <gripper_link>simple_gripper::left_finger</gripper_link>
        <gripper_link>simple_gripper::left_finger_tip</gripper_link>
        <palm_link>simple_gripper::palm</palm_link>
      </gripper>
      <plugin name='simple_arm_plugin' filename='libJointTrajectoryPlugin.so'/>
      <joint name='arm_gripper_joint' type='revolute'>
        <parent>simple_arm::arm_wrist_roll</parent>
        <child>simple_gripper::riser</child>
        <axis>
          <limit>
            <lower>0</lower>
            <upper>0</upper>
          </limit>
          <xyz>0 0 1</xyz>
          <use_parent_model_frame>1</use_parent_model_frame>
          <dynamics>
            <spring_reference>0</spring_reference>
            <spring_stiffness>0</spring_stiffness>
          </dynamics>
        </axis>
      </joint>
      <pose frame=''>-2.86961 -1.63566 0 0 -0 0</pose>
    </model>
    <model name='postbox'>
      <static>1</static>
      <link name='link'>
        <collision name='collision'>
          <geometry>
            <mesh>
              <uri>model://postbox/meshes/postbox.dae</uri>
            </mesh>
          </geometry>
          <max_contacts>10</max_contacts>
          <surface>
            <contact>
              <ode/>
            </contact>
            <bounce/>
            <friction>
              <torsional>
                <ode/>
              </torsional>
              <ode/>
            </friction>
          </surface>
        </collision>
        <visual name='visual'>
          <geometry>
            <mesh>
              <uri>model://postbox/meshes/postbox.dae</uri>
            </mesh>
          </geometry>
        </visual>
        <self_collide>0</self_collide>
        <kinematic>0</kinematic>
      </link>
      <pose frame=''>7.5063 -3.95604 0 0 -0 0</pose>
    </model>
    <model name='hammer'>
      <static>1</static>
      <link name='link'>
        <collision name='collision'>
          <geometry>
            <mesh>
              <uri>model://hammer/meshes/hammer.dae</uri>
            </mesh>
          </geometry>
          <max_contacts>10</max_contacts>
          <surface>
            <contact>
              <ode/>
            </contact>
            <bounce/>
            <friction>
              <torsional>
                <ode/>
              </torsional>
              <ode/>
            </friction>
          </surface>
        </collision>
        <visual name='visual'>
          <geometry>
            <mesh>
              <uri>model://hammer/meshes/hammer.dae</uri>
            </mesh>
          </geometry>
        </visual>
        <self_collide>0</self_collide>
        <kinematic>0</kinematic>
      </link>
      <pose frame=''>7.85873 1.38078 0 0 -0 0</pose>
    </model>
    <gui fullscreen='0'>
      <camera name='user_camera'>
        <pose frame=''>-9.64509 10.6718 17.8421 0 0.797796 -0.796124</pose>
        <view_controller>orbit</view_controller>
        <projection_type>perspective</projection_type>
      </camera>
    </gui>
    <light name='user_directional_light_0' type='directional'>
      <pose frame=''>1.41941 -1.71758 1 0 -0 0</pose>
      <diffuse>0.5 0.5 0.5 1</diffuse>
      <specular>0.1 0.1 0.1 1</specular>
      <direction>0.1 0.1 -0.9</direction>
      <attenuation>
        <range>20</range>
        <constant>0.5</constant>
        <linear>0.01</linear>
        <quadratic>0.001</quadratic>
      </attenuation>
      <cast_shadows>1</cast_shadows>
    </light>
    <model name='myrobot1'>
      <model name='robot1'>
        <link name='link_0'>
          <pose frame=''>0 0 0 0 -0 0</pose>
          <inertial>
            <mass>1</mass>
            <inertia>
              <ixx>0.166667</ixx>
              <ixy>0</ixy>
              <ixz>0</ixz>
              <iyy>0.166667</iyy>
              <iyz>0</iyz>
              <izz>0.166667</izz>
            </inertia>
            <pose frame=''>0 0 0 0 -0 0</pose>
          </inertial>
          <gravity>1</gravity>
          <self_collide>0</self_collide>
          <kinematic>0</kinematic>
          <visual name='visual'>
            <pose frame=''>0 0 0 0 -0 0</pose>
            <geometry>
              <box>
                <size>0.3 1 0.1</size>
              </box>
            </geometry>
            <material>
              <lighting>1</lighting>
              <script>
                <uri>file://media/materials/scripts/gazebo.material</uri>
                <name>Gazebo/Grey</name>
              </script>
              <shader type='pixel'>
                <normal_map>__default__</normal_map>
              </shader>
              <ambient>0.5 0 0 1</ambient>
              <diffuse>1 0 0 1</diffuse>
              <specular>0.1 0.1 0.1 1</specular>
              <emissive>0 0 0 1</emissive>
            </material>
            <transparency>0</transparency>
            <cast_shadows>1</cast_shadows>
          </visual>
          <collision name='collision'>
            <laser_retro>0</laser_retro>
            <max_contacts>10</max_contacts>
            <pose frame=''>0 0 0 0 -0 0</pose>
            <geometry>
              <box>
                <size>0.3 1 0.1</size>
              </box>
            </geometry>
            <surface>
              <friction>
                <ode>
                  <mu>1</mu>
                  <mu2>1</mu2>
                  <fdir1>0 0 0</fdir1>
                  <slip1>0</slip1>
                  <slip2>0</slip2>
                </ode>
                <torsional>
                  <coefficient>1</coefficient>
                  <patch_radius>0</patch_radius>
                  <surface_radius>0</surface_radius>
                  <use_patch_radius>1</use_patch_radius>
                  <ode>
                    <slip>0</slip>
                  </ode>
                </torsional>
              </friction>
              <bounce>
                <restitution_coefficient>0</restitution_coefficient>
                <threshold>1e+06</threshold>
              </bounce>
              <contact>
                <collide_without_contact>0</collide_without_contact>
                <collide_without_contact_bitmask>1</collide_without_contact_bitmask>
                <collide_bitmask>1</collide_bitmask>
                <ode>
                  <soft_cfm>0</soft_cfm>
                  <soft_erp>0.2</soft_erp>
                  <kp>1e+13</kp>
                  <kd>1</kd>
                  <max_vel>0.01</max_vel>
                  <min_depth>0</min_depth>
                </ode>
                <bullet>
                  <split_impulse>1</split_impulse>
                  <split_impulse_penetration_threshold>-0.01</split_impulse_penetration_threshold>
                  <soft_cfm>0</soft_cfm>
                  <soft_erp>0.2</soft_erp>
                  <kp>1e+13</kp>
                  <kd>1</kd>
                </bullet>
              </contact>
            </surface>
          </collision>
        </link>
        <link name='link_2'>
          <pose frame=''>0 -0.550019 0 1.5707 -0 0</pose>
          <inertial>
            <mass>1</mass>
            <inertia>
              <ixx>0.145833</ixx>
              <ixy>0</ixy>
              <ixz>0</ixz>
              <iyy>0.145833</iyy>
              <iyz>0</iyz>
              <izz>0.125</izz>
            </inertia>
            <pose frame=''>0 0 0 0 -0 0</pose>
          </inertial>
          <gravity>1</gravity>
          <self_collide>0</self_collide>
          <kinematic>0</kinematic>
          <visual name='visual'>
            <pose frame=''>0 0 0 0 -0 0</pose>
            <geometry>
              <cylinder>
                <radius>0.2</radius>
                <length>0.1</length>
              </cylinder>
            </geometry>
            <material>
              <lighting>1</lighting>
              <script>
                <uri>file://media/materials/scripts/gazebo.material</uri>
                <name>Gazebo/Grey</name>
              </script>
              <shader type='pixel'>
                <normal_map>__default__</normal_map>
              </shader>
              <ambient>0.3 0.3 0.3 1</ambient>
              <diffuse>0.7 0.7 0.7 1</diffuse>
              <specular>0.01 0.01 0.01 1</specular>
              <emissive>0 0 0 1</emissive>
            </material>
            <transparency>0</transparency>
            <cast_shadows>1</cast_shadows>
          </visual>
          <collision name='collision'>
            <laser_retro>0</laser_retro>
            <max_contacts>10</max_contacts>
            <pose frame=''>0 0 0 0 -0 0</pose>
            <geometry>
              <cylinder>
                <radius>0.2</radius>
                <length>0.1</length>
              </cylinder>
            </geometry>
            <surface>
              <friction>
                <ode>
                  <mu>1</mu>
                  <mu2>1</mu2>
                  <fdir1>0 0 0</fdir1>
                  <slip1>0</slip1>
                  <slip2>0</slip2>
                </ode>
                <torsional>
                  <coefficient>1</coefficient>
                  <patch_radius>0</patch_radius>
                  <surface_radius>0</surface_radius>
                  <use_patch_radius>1</use_patch_radius>
                  <ode>
                    <slip>0</slip>
                  </ode>
                </torsional>
              </friction>
              <bounce>
                <restitution_coefficient>0</restitution_coefficient>
                <threshold>1e+06</threshold>
              </bounce>
              <contact>
                <collide_without_contact>0</collide_without_contact>
                <collide_without_contact_bitmask>1</collide_without_contact_bitmask>
                <collide_bitmask>1</collide_bitmask>
                <ode>
                  <soft_cfm>0</soft_cfm>
                  <soft_erp>0.2</soft_erp>
                  <kp>1e+13</kp>
                  <kd>1</kd>
                  <max_vel>0.01</max_vel>
                  <min_depth>0</min_depth>
                </ode>
                <bullet>
                  <split_impulse>1</split_impulse>
                  <split_impulse_penetration_threshold>-0.01</split_impulse_penetration_threshold>
                  <soft_cfm>0</soft_cfm>
                  <soft_erp>0.2</soft_erp>
                  <kp>1e+13</kp>
                  <kd>1</kd>
                </bullet>
              </contact>
            </surface>
          </collision>
        </link>
        <link name='link_2_clone'>
          <pose frame=''>0 0.550019 0 1.5707 -0 0</pose>
          <inertial>
            <mass>1</mass>
            <inertia>
              <ixx>0.145833</ixx>
              <ixy>0</ixy>
              <ixz>0</ixz>
              <iyy>0.145833</iyy>
              <iyz>0</iyz>
              <izz>0.125</izz>
            </inertia>
            <pose frame=''>0 0 0 0 -0 0</pose>
          </inertial>
          <self_collide>0</self_collide>
          <kinematic>0</kinematic>
          <visual name='visual'>
            <pose frame=''>0 0 0 0 -0 0</pose>
            <geometry>
              <cylinder>
                <radius>0.2</radius>
                <length>0.1</length>
              </cylinder>
            </geometry>
            <material>
              <lighting>1</lighting>
              <script>
                <uri>file://media/materials/scripts/gazebo.material</uri>
                <name>Gazebo/Grey</name>
              </script>
              <shader type='pixel'>
                <normal_map>__default__</normal_map>
              </shader>
              <ambient>0.5 0 0 1</ambient>
              <diffuse>1 0 0 1</diffuse>
              <specular>0.1 0.1 0.1 1</specular>
              <emissive>0 0 0 1</emissive>
            </material>
            <transparency>0</transparency>
            <cast_shadows>1</cast_shadows>
          </visual>
          <collision name='collision'>
            <laser_retro>0</laser_retro>
            <max_contacts>10</max_contacts>
            <pose frame=''>0 0 0 0 -0 0</pose>
            <geometry>
              <cylinder>
                <radius>0.2</radius>
                <length>0.1</length>
              </cylinder>
            </geometry>
            <surface>
              <friction>
                <ode>
                  <mu>1</mu>
                  <mu2>1</mu2>
                  <fdir1>0 0 0</fdir1>
                  <slip1>0</slip1>
                  <slip2>0</slip2>
                </ode>
                <torsional>
                  <coefficient>1</coefficient>
                  <patch_radius>0</patch_radius>
                  <surface_radius>0</surface_radius>
                  <use_patch_radius>1</use_patch_radius>
                  <ode>
                    <slip>0</slip>
                  </ode>
                </torsional>
              </friction>
              <bounce>
                <restitution_coefficient>0</restitution_coefficient>
                <threshold>1e+06</threshold>
              </bounce>
              <contact>
                <collide_without_contact>0</collide_without_contact>
                <collide_without_contact_bitmask>1</collide_without_contact_bitmask>
                <collide_bitmask>1</collide_bitmask>
                <ode>
                  <soft_cfm>0</soft_cfm>
                  <soft_erp>0.2</soft_erp>
                  <kp>1e+13</kp>
                  <kd>1</kd>
                  <max_vel>0.01</max_vel>
                  <min_depth>0</min_depth>
                </ode>
                <bullet>
                  <split_impulse>1</split_impulse>
                  <split_impulse_penetration_threshold>-0.01</split_impulse_penetration_threshold>
                  <soft_cfm>0</soft_cfm>
                  <soft_erp>0.2</soft_erp>
                  <kp>1e+13</kp>
                  <kd>1</kd>
                </bullet>
              </contact>
            </surface>
          </collision>
        </link>
        <joint name='link_0_JOINT_0' type='revolute'>
          <parent>link_0</parent>
          <child>link_2</child>
          <pose frame=''>0 0 0 0 -0 0</pose>
          <axis>
            <xyz>0 0 1</xyz>
            <use_parent_model_frame>0</use_parent_model_frame>
            <limit>
              <lower>-1.79769e+308</lower>
              <upper>1.79769e+308</upper>
              <effort>-1</effort>
              <velocity>-1</velocity>
            </limit>
            <dynamics>
              <spring_reference>0</spring_reference>
              <spring_stiffness>0</spring_stiffness>
              <damping>0</damping>
            </dynamics>
          </axis>
          <physics>
            <ode>
              <limit>
                <cfm>0</cfm>
                <erp>0.2</erp>
              </limit>
              <suspension>
                <cfm>0</cfm>
                <erp>0.2</erp>
              </suspension>
            </ode>
          </physics>
        </joint>
        <joint name='link_0_JOINT_1' type='revolute'>
          <parent>link_0</parent>
          <child>link_2_clone</child>
          <pose frame=''>0 0 0 0 -0 0</pose>
          <axis>
            <xyz>1 0 0</xyz>
            <use_parent_model_frame>0</use_parent_model_frame>
            <limit>
              <lower>-1.79769e+308</lower>
              <upper>1.79769e+308</upper>
              <effort>-1</effort>
              <velocity>-1</velocity>
            </limit>
            <dynamics>
              <spring_reference>0</spring_reference>
              <spring_stiffness>0</spring_stiffness>
              <damping>0</damping>
            </dynamics>
          </axis>
          <physics>
            <ode>
              <limit>
                <cfm>0</cfm>
                <erp>0.2</erp>
              </limit>
              <suspension>
                <cfm>0</cfm>
                <erp>0.2</erp>
              </suspension>
            </ode>
          </physics>
        </joint>
        <static>0</static>
        <allow_auto_disable>1</allow_auto_disable>
        <pose frame=''>2e-06 0 0 0 -0 0</pose>
      </model>
      <static>0</static>
      <allow_auto_disable>1</allow_auto_disable>
      <pose frame=''>3.27227 0.965902 0 0 -0 0</pose>
    </model>
    <model name='myrobot1_0'>
      <model name='robot1'>
        <link name='link_0'>
          <pose frame=''>0 0 0 0 -0 0</pose>
          <inertial>
            <mass>1</mass>
            <inertia>
              <ixx>0.166667</ixx>
              <ixy>0</ixy>
              <ixz>0</ixz>
              <iyy>0.166667</iyy>
              <iyz>0</iyz>
              <izz>0.166667</izz>
            </inertia>
            <pose frame=''>0 0 0 0 -0 0</pose>
          </inertial>
          <gravity>1</gravity>
          <self_collide>0</self_collide>
          <kinematic>0</kinematic>
          <visual name='visual'>
            <pose frame=''>0 0 0 0 -0 0</pose>
            <geometry>
              <box>
                <size>0.3 1 0.1</size>
              </box>
            </geometry>
            <material>
              <lighting>1</lighting>
              <script>
                <uri>file://media/materials/scripts/gazebo.material</uri>
                <name>Gazebo/Grey</name>
              </script>
              <shader type='pixel'>
                <normal_map>__default__</normal_map>
              </shader>
              <ambient>0.5 0 0 1</ambient>
              <diffuse>1 0 0 1</diffuse>
              <specular>0.1 0.1 0.1 1</specular>
              <emissive>0 0 0 1</emissive>
            </material>
            <transparency>0</transparency>
            <cast_shadows>1</cast_shadows>
          </visual>
          <collision name='collision'>
            <laser_retro>0</laser_retro>
            <max_contacts>10</max_contacts>
            <pose frame=''>0 0 0 0 -0 0</pose>
            <geometry>
              <box>
                <size>0.3 1 0.1</size>
              </box>
            </geometry>
            <surface>
              <friction>
                <ode>
                  <mu>1</mu>
                  <mu2>1</mu2>
                  <fdir1>0 0 0</fdir1>
                  <slip1>0</slip1>
                  <slip2>0</slip2>
                </ode>
                <torsional>
                  <coefficient>1</coefficient>
                  <patch_radius>0</patch_radius>
                  <surface_radius>0</surface_radius>
                  <use_patch_radius>1</use_patch_radius>
                  <ode>
                    <slip>0</slip>
                  </ode>
                </torsional>
              </friction>
              <bounce>
                <restitution_coefficient>0</restitution_coefficient>
                <threshold>1e+06</threshold>
              </bounce>
              <contact>
                <collide_without_contact>0</collide_without_contact>
                <collide_without_contact_bitmask>1</collide_without_contact_bitmask>
                <collide_bitmask>1</collide_bitmask>
                <ode>
                  <soft_cfm>0</soft_cfm>
                  <soft_erp>0.2</soft_erp>
                  <kp>1e+13</kp>
                  <kd>1</kd>
                  <max_vel>0.01</max_vel>
                  <min_depth>0</min_depth>
                </ode>
                <bullet>
                  <split_impulse>1</split_impulse>
                  <split_impulse_penetration_threshold>-0.01</split_impulse_penetration_threshold>
                  <soft_cfm>0</soft_cfm>
                  <soft_erp>0.2</soft_erp>
                  <kp>1e+13</kp>
                  <kd>1</kd>
                </bullet>
              </contact>
            </surface>
          </collision>
        </link>
        <link name='link_2'>
          <pose frame=''>0 -0.550019 0 1.5707 -0 0</pose>
          <inertial>
            <mass>1</mass>
            <inertia>
              <ixx>0.145833</ixx>
              <ixy>0</ixy>
              <ixz>0</ixz>
              <iyy>0.145833</iyy>
              <iyz>0</iyz>
              <izz>0.125</izz>
            </inertia>
            <pose frame=''>0 0 0 0 -0 0</pose>
          </inertial>
          <gravity>1</gravity>
          <self_collide>0</self_collide>
          <kinematic>0</kinematic>
          <visual name='visual'>
            <pose frame=''>0 0 0 0 -0 0</pose>
            <geometry>
              <cylinder>
                <radius>0.2</radius>
                <length>0.1</length>
              </cylinder>
            </geometry>
            <material>
              <lighting>1</lighting>
              <script>
                <uri>file://media/materials/scripts/gazebo.material</uri>
                <name>Gazebo/Grey</name>
              </script>
              <shader type='pixel'>
                <normal_map>__default__</normal_map>
              </shader>
              <ambient>0.3 0.3 0.3 1</ambient>
              <diffuse>0.7 0.7 0.7 1</diffuse>
              <specular>0.01 0.01 0.01 1</specular>
              <emissive>0 0 0 1</emissive>
            </material>
            <transparency>0</transparency>
            <cast_shadows>1</cast_shadows>
          </visual>
          <collision name='collision'>
            <laser_retro>0</laser_retro>
            <max_contacts>10</max_contacts>
            <pose frame=''>0 0 0 0 -0 0</pose>
            <geometry>
              <cylinder>
                <radius>0.2</radius>
                <length>0.1</length>
              </cylinder>
            </geometry>
            <surface>
              <friction>
                <ode>
                  <mu>1</mu>
                  <mu2>1</mu2>
                  <fdir1>0 0 0</fdir1>
                  <slip1>0</slip1>
                  <slip2>0</slip2>
                </ode>
                <torsional>
                  <coefficient>1</coefficient>
                  <patch_radius>0</patch_radius>
                  <surface_radius>0</surface_radius>
                  <use_patch_radius>1</use_patch_radius>
                  <ode>
                    <slip>0</slip>
                  </ode>
                </torsional>
              </friction>
              <bounce>
                <restitution_coefficient>0</restitution_coefficient>
                <threshold>1e+06</threshold>
              </bounce>
              <contact>
                <collide_without_contact>0</collide_without_contact>
                <collide_without_contact_bitmask>1</collide_without_contact_bitmask>
                <collide_bitmask>1</collide_bitmask>
                <ode>
                  <soft_cfm>0</soft_cfm>
                  <soft_erp>0.2</soft_erp>
                  <kp>1e+13</kp>
                  <kd>1</kd>
                  <max_vel>0.01</max_vel>
                  <min_depth>0</min_depth>
                </ode>
                <bullet>
                  <split_impulse>1</split_impulse>
                  <split_impulse_penetration_threshold>-0.01</split_impulse_penetration_threshold>
                  <soft_cfm>0</soft_cfm>
                  <soft_erp>0.2</soft_erp>
                  <kp>1e+13</kp>
                  <kd>1</kd>
                </bullet>
              </contact>
            </surface>
          </collision>
        </link>
        <link name='link_2_clone'>
          <pose frame=''>0 0.550019 0 1.5707 -0 0</pose>
          <inertial>
            <mass>1</mass>
            <inertia>
              <ixx>0.145833</ixx>
              <ixy>0</ixy>
              <ixz>0</ixz>
              <iyy>0.145833</iyy>
              <iyz>0</iyz>
              <izz>0.125</izz>
            </inertia>
            <pose frame=''>0 0 0 0 -0 0</pose>
          </inertial>
          <self_collide>0</self_collide>
          <kinematic>0</kinematic>
          <visual name='visual'>
            <pose frame=''>0 0 0 0 -0 0</pose>
            <geometry>
              <cylinder>
                <radius>0.2</radius>
                <length>0.1</length>
              </cylinder>
            </geometry>
            <material>
              <lighting>1</lighting>
              <script>
                <uri>file://media/materials/scripts/gazebo.material</uri>
                <name>Gazebo/Grey</name>
              </script>
              <shader type='pixel'>
                <normal_map>__default__</normal_map>
              </shader>
              <ambient>0.5 0 0 1</ambient>
              <diffuse>1 0 0 1</diffuse>
              <specular>0.1 0.1 0.1 1</specular>
              <emissive>0 0 0 1</emissive>
            </material>
            <transparency>0</transparency>
            <cast_shadows>1</cast_shadows>
          </visual>
          <collision name='collision'>
            <laser_retro>0</laser_retro>
            <max_contacts>10</max_contacts>
            <pose frame=''>0 0 0 0 -0 0</pose>
            <geometry>
              <cylinder>
                <radius>0.2</radius>
                <length>0.1</length>
              </cylinder>
            </geometry>
            <surface>
              <friction>
                <ode>
                  <mu>1</mu>
                  <mu2>1</mu2>
                  <fdir1>0 0 0</fdir1>
                  <slip1>0</slip1>
                  <slip2>0</slip2>
                </ode>
                <torsional>
                  <coefficient>1</coefficient>
                  <patch_radius>0</patch_radius>
                  <surface_radius>0</surface_radius>
                  <use_patch_radius>1</use_patch_radius>
                  <ode>
                    <slip>0</slip>
                  </ode>
                </torsional>
              </friction>
              <bounce>
                <restitution_coefficient>0</restitution_coefficient>
                <threshold>1e+06</threshold>
              </bounce>
              <contact>
                <collide_without_contact>0</collide_without_contact>
                <collide_without_contact_bitmask>1</collide_without_contact_bitmask>
                <collide_bitmask>1</collide_bitmask>
                <ode>
                  <soft_cfm>0</soft_cfm>
                  <soft_erp>0.2</soft_erp>
                  <kp>1e+13</kp>
                  <kd>1</kd>
                  <max_vel>0.01</max_vel>
                  <min_depth>0</min_depth>
                </ode>
                <bullet>
                  <split_impulse>1</split_impulse>
                  <split_impulse_penetration_threshold>-0.01</split_impulse_penetration_threshold>
                  <soft_cfm>0</soft_cfm>
                  <soft_erp>0.2</soft_erp>
                  <kp>1e+13</kp>
                  <kd>1</kd>
                </bullet>
              </contact>
            </surface>
          </collision>
        </link>
        <joint name='link_0_JOINT_0' type='revolute'>
          <parent>link_0</parent>
          <child>link_2</child>
          <pose frame=''>0 0 0 0 -0 0</pose>
          <axis>
            <xyz>0 0 1</xyz>
            <use_parent_model_frame>0</use_parent_model_frame>
            <limit>
              <lower>-1.79769e+308</lower>
              <upper>1.79769e+308</upper>
              <effort>-1</effort>
              <velocity>-1</velocity>
            </limit>
            <dynamics>
              <spring_reference>0</spring_reference>
              <spring_stiffness>0</spring_stiffness>
              <damping>0</damping>
            </dynamics>
          </axis>
          <physics>
            <ode>
              <limit>
                <cfm>0</cfm>
                <erp>0.2</erp>
              </limit>
              <suspension>
                <cfm>0</cfm>
                <erp>0.2</erp>
              </suspension>
            </ode>
          </physics>
        </joint>
        <joint name='link_0_JOINT_1' type='revolute'>
          <parent>link_0</parent>
          <child>link_2_clone</child>
          <pose frame=''>0 0 0 0 -0 0</pose>
          <axis>
            <xyz>1 0 0</xyz>
            <use_parent_model_frame>0</use_parent_model_frame>
            <limit>
              <lower>-1.79769e+308</lower>
              <upper>1.79769e+308</upper>
              <effort>-1</effort>
              <velocity>-1</velocity>
            </limit>
            <dynamics>
              <spring_reference>0</spring_reference>
              <spring_stiffness>0</spring_stiffness>
              <damping>0</damping>
            </dynamics>
          </axis>
          <physics>
            <ode>
              <limit>
                <cfm>0</cfm>
                <erp>0.2</erp>
              </limit>
              <suspension>
                <cfm>0</cfm>
                <erp>0.2</erp>
              </suspension>
            </ode>
          </physics>
        </joint>
        <static>0</static>
        <allow_auto_disable>1</allow_auto_disable>
        <pose frame=''>2e-06 0 0 0 -0 0</pose>
      </model>
      <static>0</static>
      <allow_auto_disable>1</allow_auto_disable>
      <pose frame=''>0.793476 -3.31056 0 0 -0 0</pose>
    </model>
  </world>
</sdf>
